18-Mar-22 20:52:52 CRITICAL Mimikatz detected agent_name=SUPRAM object_name=lsass.exe process=mimikatz.exe process_path=D:\ELK\Development\mimikatz-master\mimikatz-master\x64\mimikatz.exe event_id=4656 access_mask=0x1010
18-Mar-22 21:13:23 CRITICAL Mimikatz detected agent_name=SUPRAM object_name=lsass.exe process=mimikatz.exe process_path=D:\ELK\Development\mimikatz-master\mimikatz-master\x64\mimikatz.exe event_id=4656 access_mask=0x1010
18-Mar-22 21:13:48 CRITICAL Mimikatz detected agent_name=SUPRAM object_name=lsass.exe process=mimikatz.exe process_path=D:\ELK\Development\mimikatz-master\mimikatz-master\x64\mimikatz.exe event_id=4656 access_mask=0x1010
18-Mar-22 21:27:46 CRITICAL Mimikatz detected agent_name=SUPRAM object_name=lsass.exe process=mimikatz.exe process_path=D:\ELK\Development\mimikatz-master\mimikatz-master\x64\mimikatz.exe event_id=4656 access_mask=0x1010
18-Mar-22 21:30:24 CRITICAL BruteForce Attempts number_of_attempts=30 username=piyush program=sshd ip_address=192.168.1.71 
18-Mar-22 21:43:40 WARNING POST http://192.168.1.71:9200/authentication_failed_index/_search [status:N/A request:10.013s]
Traceback (most recent call last):
  File "D:\ELK\Development\ASID-Tool\env\lib\site-packages\urllib3\connectionpool.py", line 449, in _make_request
    six.raise_from(e, None)
  File "<string>", line 3, in raise_from
  File "D:\ELK\Development\ASID-Tool\env\lib\site-packages\urllib3\connectionpool.py", line 444, in _make_request
    httplib_response = conn.getresponse()
  File "C:\Users\absult\AppData\Local\Programs\Python\Python39\lib\http\client.py", line 1371, in getresponse
    response.begin()
  File "C:\Users\absult\AppData\Local\Programs\Python\Python39\lib\http\client.py", line 319, in begin
    version, status, reason = self._read_status()
  File "C:\Users\absult\AppData\Local\Programs\Python\Python39\lib\http\client.py", line 280, in _read_status
    line = str(self.fp.readline(_MAXLINE + 1), "iso-8859-1")
  File "C:\Users\absult\AppData\Local\Programs\Python\Python39\lib\socket.py", line 704, in readinto
    return self._sock.recv_into(b)
socket.timeout: timed out

During handling of the above exception, another exception occurred:

Traceback (most recent call last):
  File "D:\ELK\Development\ASID-Tool\env\lib\site-packages\elasticsearch\connection\http_urllib3.py", line 255, in perform_request
    response = self.pool.urlopen(
  File "D:\ELK\Development\ASID-Tool\env\lib\site-packages\urllib3\connectionpool.py", line 785, in urlopen
    retries = retries.increment(
  File "D:\ELK\Development\ASID-Tool\env\lib\site-packages\urllib3\util\retry.py", line 525, in increment
    raise six.reraise(type(error), error, _stacktrace)
  File "D:\ELK\Development\ASID-Tool\env\lib\site-packages\urllib3\packages\six.py", line 770, in reraise
    raise value
  File "D:\ELK\Development\ASID-Tool\env\lib\site-packages\urllib3\connectionpool.py", line 703, in urlopen
    httplib_response = self._make_request(
  File "D:\ELK\Development\ASID-Tool\env\lib\site-packages\urllib3\connectionpool.py", line 451, in _make_request
    self._raise_timeout(err=e, url=url, timeout_value=read_timeout)
  File "D:\ELK\Development\ASID-Tool\env\lib\site-packages\urllib3\connectionpool.py", line 340, in _raise_timeout
    raise ReadTimeoutError(
urllib3.exceptions.ReadTimeoutError: HTTPConnectionPool(host='192.168.1.71', port=9200): Read timed out. (read timeout=10)
